Traceback (most recent call last):
  File "/Users/yusufdanisman/anaconda3/lib/python3.11/site-packages/jupyter_cache/executors/utils.py", line 58, in single_nb_execution
    executenb(
  File "/Users/yusufdanisman/anaconda3/lib/python3.11/site-packages/nbclient/client.py", line 1305, in execute
    return NotebookClient(nb=nb, resources=resources, km=km, **kwargs).execute()
           ^^^^^^^^^^^^^^^^^^^^^^^^^^^^^^^^^^^^^^^^^^^^^^^^^^^^^^^^^^^^^^^^^^^^^
  File "/Users/yusufdanisman/anaconda3/lib/python3.11/site-packages/jupyter_core/utils/__init__.py", line 173, in wrapped
    return loop.run_until_complete(inner)
           ^^^^^^^^^^^^^^^^^^^^^^^^^^^^^^
  File "/Users/yusufdanisman/anaconda3/lib/python3.11/asyncio/base_events.py", line 654, in run_until_complete
    return future.result()
           ^^^^^^^^^^^^^^^
  File "/Users/yusufdanisman/anaconda3/lib/python3.11/site-packages/nbclient/client.py", line 705, in async_execute
    await self.async_execute_cell(
  File "/Users/yusufdanisman/anaconda3/lib/python3.11/site-packages/nbclient/client.py", line 1058, in async_execute_cell
    await self._check_raise_for_error(cell, cell_index, exec_reply)
  File "/Users/yusufdanisman/anaconda3/lib/python3.11/site-packages/nbclient/client.py", line 914, in _check_raise_for_error
    raise CellExecutionError.from_cell_and_msg(cell, exec_reply_content)
nbclient.exceptions.CellExecutionError: An error occurred while executing the following cell:
------------------
import string
plt.figure(figsize=(20,3))
cs(5,3,1,0, x= 1)
cs(3,3,1,0, x= 2)
cs(3,3,1,1, x= 3)
cs(4,3,1,1, x= 4)

cs(5,1,3,0, x= 5)
cs(3,1,3,0, x= 6)
cs(3,1,3,1, x= 7)
cs(4,1,3,1, x= 8)


cs(4,3,3,1, x= 9)
cs(2,2,2,1, x=10)
cs(2,2,2,2, x=11)
cs(3,2,2,2, x=12)

plt.xticks(range(1,13), list(string.ascii_lowercase[:12]), fontsize=20);
------------------


[0;31m---------------------------------------------------------------------------[0m
[0;31mTypeError[0m                                 Traceback (most recent call last)
Cell [0;32mIn[16], line 3[0m
[1;32m      1[0m [38;5;28;01mimport[39;00m [38;5;21;01mstring[39;00m
[1;32m      2[0m plt[38;5;241m.[39mfigure(figsize[38;5;241m=[39m([38;5;241m20[39m,[38;5;241m3[39m))
[0;32m----> 3[0m cs([38;5;241m5[39m,[38;5;241m3[39m,[38;5;241m1[39m,[38;5;241m0[39m, x[38;5;241m=[39m [38;5;241m1[39m)
[1;32m      4[0m cs([38;5;241m3[39m,[38;5;241m3[39m,[38;5;241m1[39m,[38;5;241m0[39m, x[38;5;241m=[39m [38;5;241m2[39m)
[1;32m      5[0m cs([38;5;241m3[39m,[38;5;241m3[39m,[38;5;241m1[39m,[38;5;241m1[39m, x[38;5;241m=[39m [38;5;241m3[39m)

[0;31mTypeError[0m: cs() got multiple values for argument 'x'

