Traceback (most recent call last):
  File "/Users/yusufdanisman/anaconda3/lib/python3.11/site-packages/jupyter_cache/executors/utils.py", line 58, in single_nb_execution
    executenb(
  File "/Users/yusufdanisman/anaconda3/lib/python3.11/site-packages/nbclient/client.py", line 1305, in execute
    return NotebookClient(nb=nb, resources=resources, km=km, **kwargs).execute()
           ^^^^^^^^^^^^^^^^^^^^^^^^^^^^^^^^^^^^^^^^^^^^^^^^^^^^^^^^^^^^^^^^^^^^^
  File "/Users/yusufdanisman/anaconda3/lib/python3.11/site-packages/jupyter_core/utils/__init__.py", line 173, in wrapped
    return loop.run_until_complete(inner)
           ^^^^^^^^^^^^^^^^^^^^^^^^^^^^^^
  File "/Users/yusufdanisman/anaconda3/lib/python3.11/asyncio/base_events.py", line 653, in run_until_complete
    return future.result()
           ^^^^^^^^^^^^^^^
  File "/Users/yusufdanisman/anaconda3/lib/python3.11/site-packages/nbclient/client.py", line 705, in async_execute
    await self.async_execute_cell(
  File "/Users/yusufdanisman/anaconda3/lib/python3.11/site-packages/nbclient/client.py", line 1058, in async_execute_cell
    await self._check_raise_for_error(cell, cell_index, exec_reply)
  File "/Users/yusufdanisman/anaconda3/lib/python3.11/site-packages/nbclient/client.py", line 914, in _check_raise_for_error
    raise CellExecutionError.from_cell_and_msg(cell, exec_reply_content)
nbclient.exceptions.CellExecutionError: An error occurred while executing the following cell:
------------------
import random
number_list = tuple(range(1,10))
random.shuffle(number_list)

for i in range(3):
  print('-'*7)
  for j in range(3):
    print(f'|{number_list[3*i+j]}', end='')
  print('|')
print('-'*7)
------------------


[0;31m---------------------------------------------------------------------------[0m
[0;31mTypeError[0m                                 Traceback (most recent call last)
Cell [0;32mIn[18], line 3[0m
[1;32m      1[0m [38;5;28;01mimport[39;00m [38;5;21;01mrandom[39;00m
[1;32m      2[0m number_list [38;5;241m=[39m [38;5;28mtuple[39m([38;5;28mrange[39m([38;5;241m1[39m,[38;5;241m10[39m))
[0;32m----> 3[0m random[38;5;241m.[39mshuffle(number_list)
[1;32m      5[0m [38;5;28;01mfor[39;00m i [38;5;129;01min[39;00m [38;5;28mrange[39m([38;5;241m3[39m):
[1;32m      6[0m   [38;5;28mprint[39m([38;5;124m'[39m[38;5;124m-[39m[38;5;124m'[39m[38;5;241m*[39m[38;5;241m7[39m)

File [0;32m~/anaconda3/lib/python3.11/random.py:383[0m, in [0;36mRandom.shuffle[0;34m(self, x)[0m
[1;32m    380[0m [38;5;28;01mfor[39;00m i [38;5;129;01min[39;00m [38;5;28mreversed[39m([38;5;28mrange[39m([38;5;241m1[39m, [38;5;28mlen[39m(x))):
[1;32m    381[0m     [38;5;66;03m# pick an element in x[:i+1] with which to exchange x[i][39;00m
[1;32m    382[0m     j [38;5;241m=[39m randbelow(i [38;5;241m+[39m [38;5;241m1[39m)
[0;32m--> 383[0m     x[i], x[j] [38;5;241m=[39m x[j], x[i]

[0;31mTypeError[0m: 'tuple' object does not support item assignment

